[2024-01-09T12:57:03.560+0000] {processor.py:161} INFO - Started process (PID=637) to work on /opt/airflow/dags/data/gcs_to_bigquery_practice.py
[2024-01-09T12:57:03.564+0000] {processor.py:830} INFO - Processing file /opt/airflow/dags/data/gcs_to_bigquery_practice.py for tasks to queue
[2024-01-09T12:57:03.570+0000] {logging_mixin.py:188} INFO - [2024-01-09T12:57:03.569+0000] {dagbag.py:538} INFO - Filling up the DagBag from /opt/airflow/dags/data/gcs_to_bigquery_practice.py
[2024-01-09T12:57:03.670+0000] {processor.py:840} INFO - DAG(s) 'electricity_consumption' retrieved from /opt/airflow/dags/data/gcs_to_bigquery_practice.py
[2024-01-09T12:57:03.697+0000] {logging_mixin.py:188} INFO - [2024-01-09T12:57:03.695+0000] {dag.py:3033} INFO - Sync 1 DAGs
[2024-01-09T12:57:03.797+0000] {logging_mixin.py:188} INFO - [2024-01-09T12:57:03.796+0000] {dag.py:3820} INFO - Setting next_dagrun for electricity_consumption to 2024-01-01T00:00:00+00:00, run_after=2024-02-01T00:00:00+00:00
[2024-01-09T12:57:03.906+0000] {processor.py:183} INFO - Processing /opt/airflow/dags/data/gcs_to_bigquery_practice.py took 0.357 seconds
[2024-01-09T12:57:34.094+0000] {processor.py:161} INFO - Started process (PID=697) to work on /opt/airflow/dags/data/gcs_to_bigquery_practice.py
[2024-01-09T12:57:34.098+0000] {processor.py:830} INFO - Processing file /opt/airflow/dags/data/gcs_to_bigquery_practice.py for tasks to queue
[2024-01-09T12:57:34.102+0000] {logging_mixin.py:188} INFO - [2024-01-09T12:57:34.101+0000] {dagbag.py:538} INFO - Filling up the DagBag from /opt/airflow/dags/data/gcs_to_bigquery_practice.py
[2024-01-09T12:57:34.168+0000] {processor.py:840} INFO - DAG(s) 'electricity_consumption' retrieved from /opt/airflow/dags/data/gcs_to_bigquery_practice.py
[2024-01-09T12:57:34.194+0000] {logging_mixin.py:188} INFO - [2024-01-09T12:57:34.191+0000] {dag.py:3033} INFO - Sync 1 DAGs
[2024-01-09T12:57:34.261+0000] {logging_mixin.py:188} INFO - [2024-01-09T12:57:34.261+0000] {dag.py:3820} INFO - Setting next_dagrun for electricity_consumption to 2024-01-01T00:00:00+00:00, run_after=2024-02-01T00:00:00+00:00
[2024-01-09T12:57:34.294+0000] {processor.py:186} ERROR - Got an exception! Propagating...
Traceback (most recent call last):
  File "/home/airflow/.local/lib/python3.10/site-packages/airflow/dag_processing/processor.py", line 182, in _run_file_processor
    _handle_dag_file_processing()
  File "/home/airflow/.local/lib/python3.10/site-packages/airflow/dag_processing/processor.py", line 163, in _handle_dag_file_processing
    result: tuple[int, int] = dag_file_processor.process_file(
  File "/home/airflow/.local/lib/python3.10/site-packages/airflow/utils/session.py", line 79, in wrapper
    return func(*args, session=session, **kwargs)
  File "/home/airflow/.local/lib/python3.10/site-packages/airflow/dag_processing/processor.py", line 859, in process_file
    serialize_errors = DagFileProcessor.save_dag_to_db(
  File "/home/airflow/.local/lib/python3.10/site-packages/airflow/api_internal/internal_api_call.py", line 114, in wrapper
    return func(*args, **kwargs)
  File "/home/airflow/.local/lib/python3.10/site-packages/airflow/utils/session.py", line 79, in wrapper
    return func(*args, session=session, **kwargs)
  File "/home/airflow/.local/lib/python3.10/site-packages/airflow/dag_processing/processor.py", line 895, in save_dag_to_db
    import_errors = DagBag._sync_to_db(dags=dags, processor_subdir=dag_directory, session=session)
  File "/home/airflow/.local/lib/python3.10/site-packages/airflow/utils/session.py", line 76, in wrapper
    return func(*args, **kwargs)
  File "/home/airflow/.local/lib/python3.10/site-packages/airflow/models/dagbag.py", line 657, in _sync_to_db
    for attempt in run_with_db_retries(logger=log):
  File "/home/airflow/.local/lib/python3.10/site-packages/tenacity/__init__.py", line 347, in __iter__
    do = self.iter(retry_state=retry_state)
  File "/home/airflow/.local/lib/python3.10/site-packages/tenacity/__init__.py", line 314, in iter
    return fut.result()
  File "/usr/local/lib/python3.10/concurrent/futures/_base.py", line 451, in result
    return self.__get_result()
  File "/usr/local/lib/python3.10/concurrent/futures/_base.py", line 403, in __get_result
    raise self._exception
  File "/home/airflow/.local/lib/python3.10/site-packages/airflow/models/dagbag.py", line 673, in _sync_to_db
    DAG.bulk_write_to_db(dags.values(), processor_subdir=processor_subdir, session=session)
  File "/home/airflow/.local/lib/python3.10/site-packages/airflow/utils/session.py", line 76, in wrapper
    return func(*args, **kwargs)
  File "/home/airflow/.local/lib/python3.10/site-packages/airflow/models/dag.py", line 3144, in bulk_write_to_db
    DagCode.bulk_sync_to_db(filelocs, session=session)
  File "/home/airflow/.local/lib/python3.10/site-packages/airflow/utils/session.py", line 76, in wrapper
    return func(*args, **kwargs)
  File "/home/airflow/.local/lib/python3.10/site-packages/airflow/models/dagcode.py", line 119, in bulk_sync_to_db
    os.path.getmtime(correct_maybe_zipped(fileloc)), tz=timezone.utc
  File "/usr/local/lib/python3.10/genericpath.py", line 55, in getmtime
    return os.stat(filename).st_mtime
FileNotFoundError: [Errno 2] No such file or directory: '/opt/airflow/dags/data/gcs_to_bigquery_practice.py'
